<?xml version="1.0" ?>
<robot name="moobot" xmlns:xacro="http://ros.org/wiki/xacro">
  <xacro:include filename="$(find moobot_description)/urdf/common_properties.xacro"/>
  <xacro:include filename="$(find moobot_description)/urdf/moobot.gazebo.xacro"/>

<!-- AGV Base -->

<link name="base_link">
    <visual>
      <!-- <origin xyz="0 0 0.0756" rpy="0 0 0"/> -->
      <origin xyz="0 0 0" rpy="0 0 0"/>
      <geometry>
        <mesh filename="package://moobot_description/mesh/agv_base_conveyor.stl" scale="0.001 0.001 0.001"/>
      </geometry>
    </visual>

    <collision>
      <origin xyz="0 0 0.132501" rpy="0 0 0"/>
      <!-- <origin xyz="0 0 0.1562185" rpy="0 0 0"/> -->
      <geometry>
        <box size="0.877615 0.701947 0.17"/>
        <!-- <box size="0.877615 0.701947 0.217435"/> --> 
      </geometry>
    </collision>
    
    <inertial>
      <origin xyz="0 0 0.1562185" rpy="0 0 0"/>
      <mass value="61"/>
      <inertia ixx="2.745" ixy="0" ixz="0"
               iyy="4.1556" iyz="0"
               izz="6.42" />
    </inertial>
  </link>

<link name="base_footprint"/>

  <joint name="base_joint" type="fixed">
    <parent link="base_footprint"/>
    <child link="base_link" />
    <origin xyz="0 0 0" rpy="0 0 0"/>
  </joint>

<link name="imu_link"/>

  <joint name="imu_joint" type="fixed">
    <parent link="base_link"/>
    <child link="imu_link" />
    <origin xyz="0 0 0" rpy="0 0 0"/>
  </joint>

<!-- Wheels -->

  <!-- Main -->
    <joint name="right_wheel_joint" type="continuous">
    <parent link="base_link"/>
    <child link="right_wheel_link"/>
    <origin xyz="0 -0.296 0.1" rpy="-1.570796 0 0"/>
    <axis xyz="0 0 1"/>
    <dynamics damping="1" friction="0"/>
    <limit effort="2" velocity="1.0"/>
    </joint>

<link name="right_wheel_link">
    <visual>
      <origin xyz="0 0 0" rpy="0 0 0"/>
      <geometry>
        <cylinder length="0.03" radius="0.1"/>
      </geometry>
    </visual>

    <collision>
      <origin xyz="0 0 0" rpy="0 0 0"/>
      <geometry>
        <cylinder length="0.03" radius="0.1"/>
      </geometry>
    </collision>
    
    <inertial>
      <origin xyz="0 0 0" rpy="0 0 0"/>
      <mass value="1"/>
      <inertia ixx="0.0025750" ixy="0" ixz="0"
               iyy="0.0025750" iyz="0"
               izz="0.0050000" />
    </inertial>
  </link>

    <joint name="left_wheel_joint" type="continuous">
    <parent link="base_link"/>
    <child link="left_wheel_link"/>
    <origin xyz="0 0.296 0.1" rpy="-1.570796 0 0"/>
    <axis xyz="0 0 1"/>
    <dynamics damping="1" friction="0"/>
    <limit effort="2" velocity="1.0"/>
    </joint>

<link name="left_wheel_link">
    <visual>
      <origin xyz="0 0 0" rpy="0 0 0"/>
      <geometry>
        <cylinder length="0.03" radius="0.1"/>
      </geometry>
    </visual>

    <collision>
      <origin xyz="0 0 0" rpy="0 0 0"/>
      <geometry>
        <cylinder length="0.03" radius="0.1"/>
      </geometry>
    </collision>
    
    <inertial>
      <origin xyz="0 0 0" rpy="0 0 0"/>
      <mass value="1"/>
      <inertia ixx="0.0025750" ixy="0" ixz="0"
               iyy="0.0025750" iyz="0"
               izz="0.0050000" />
    </inertial>
  </link>

<!-- Caster Carriers -->

  <joint name="FRCC_joint" type="continuous">
    <parent link="base_link"/>
    <child link="FRCC_link"/>
    <origin xyz="0.34075 -0.219215 0.11955" rpy="-1.570796 0 0"/>
    <axis xyz="0 1 0"/>
    </joint>

<link name="FRCC_link">
    <visual>
      <origin xyz="0 0 0" rpy="0 0 0"/>
      <geometry>
        <mesh filename="package://moobot_description/mesh/avare_tutucu_coarse.stl" scale="0.001 0.001 0.001"/>
      </geometry>
    </visual>

    <collision>
      <origin xyz="0 0.0305 0" rpy="0 0 0"/>
      <geometry>
        <box size="0.020 0.020 0.020"/>
      </geometry>
    </collision>
    
    <inertial>
      <origin xyz="0 0.0505 0" rpy="0 0 0"/>
      <mass value="0.1"/>
      <inertia ixx="0.00007" ixy="0" ixz="0"
               iyy="0.0001" iyz="0"
               izz="0.00007" />
    </inertial>
  </link>

  <joint name="FLCC_joint" type="continuous">
    <parent link="base_link"/>
    <child link="FLCC_link"/>
    <origin xyz="0.34075 0.219215 0.11955" rpy="-1.570796 0 0"/>
    <axis xyz="0 1 0"/>
    </joint>

<link name="FLCC_link">
    <visual>
      <origin xyz="0 0 0" rpy="0 0 0"/>
      <geometry>
        <mesh filename="package://moobot_description/mesh/avare_tutucu_coarse.stl" scale="0.001 0.001 0.001"/>
      </geometry>
    </visual>

    <collision>
      <origin xyz="0 0.0305 0" rpy="0 0 0"/>
      <geometry>
        <box size="0.020 0.020 0.020"/>
      </geometry>
    </collision>
    
    <inertial>
      <origin xyz="0 0.0505 0" rpy="0 0 0"/>
      <mass value="0.1"/>
      <inertia ixx="0.00007" ixy="0" ixz="0"
               iyy="0.0001" iyz="0"
               izz="0.00007" />
    </inertial>
  </link>

  <joint name="RLCC_joint" type="continuous">
    <parent link="base_link"/>
    <child link="RLCC_link"/>
    <origin xyz="-0.34075 0.219215 0.11955" rpy="-1.570796 0 0"/>
    <axis xyz="0 1 0"/>
    </joint>

<link name="RLCC_link">
    <visual>
      <origin xyz="0 0 0" rpy="0 0 0"/>
      <geometry>
        <mesh filename="package://moobot_description/mesh/avare_tutucu_coarse.stl" scale="0.001 0.001 0.001"/>
      </geometry>
    </visual>

    <collision>
      <origin xyz="0 0.0305 0" rpy="0 0 0"/>
      <geometry>
        <box size="0.020 0.020 0.020"/>
      </geometry>
    </collision>
    
    <inertial>
      <origin xyz="0 0.0505 0" rpy="0 0 0"/>
      <mass value="0.1"/>
      <inertia ixx="0.00007" ixy="0" ixz="0"
               iyy="0.0001" iyz="0"
               izz="0.00007" />
    </inertial>
  </link>

    <joint name="RRCC_joint" type="continuous">
    <parent link="base_link"/>
    <child link="RRCC_link"/>
    <origin xyz="-0.34075 -0.219215 0.11955" rpy="-1.570796 0 0"/>
    <axis xyz="0 1 0"/>
    </joint>

<link name="RRCC_link">
    <visual>
      <origin xyz="0 0 0" rpy="0 0 0"/>
      <geometry>
        <mesh filename="package://moobot_description/mesh/avare_tutucu_coarse.stl" scale="0.001 0.001 0.001"/>
      </geometry>
    </visual>

    <collision>
      <origin xyz="0 0.0305 0" rpy="0 0 0"/>
      <geometry>
        <box size="0.020 0.020 0.020"/>
      </geometry>
    </collision>
    
    <inertial>
      <origin xyz="0 0.0505 0" rpy="0 0 0"/>
      <mass value="0.1"/>
      <inertia ixx="0.00007" ixy="0" ixz="0"
               iyy="0.0001" iyz="0"
               izz="0.00007" />
    </inertial>
  </link>

<!-- Caster Wheels -->

    <joint name="FRC_joint" type="continuous">
    <parent link="FRCC_link"/>
    <child link="FRC_link"/>
    <origin xyz="-0.0265 0.08205 0" rpy="1.570796 -1.570796 0"/>
    <axis xyz="1 0 0"/> 
    </joint>

<link name="FRC_link">
    <visual>
      <origin xyz="0 0 0" rpy="0 0 0"/>
      <geometry>
        <mesh filename="package://moobot_description/mesh/avare_teker_coarse.stl" scale="0.001 0.001 0.001"/>
      </geometry> 
    </visual>

    <collision>
      <origin xyz="0 0 0" rpy="0 1.570796 0"/>
      <geometry>
        <cylinder length="0.022" radius="0.0375"/>
      </geometry>
    </collision>
    
    <inertial>
      <origin xyz="0 0 0" rpy="0 0 0"/>
      <mass value="0.1"/>
      <inertia ixx="0.0002" ixy="0" ixz="0"
               iyy="0.0002" iyz="0"
               izz="0.0002" />
    </inertial>
  </link>

  <joint name="FLC_joint" type="continuous">
    <parent link="FLCC_link"/>
    <child link="FLC_link"/>
    <origin xyz="-0.0265 0.08205 0" rpy="1.570796 -1.570796 0"/>
    <axis xyz="1 0 0"/>
  </joint>

<link name="FLC_link">
    <visual>
      <origin xyz="0 0 0" rpy="0 0 0"/>
      <geometry>
        <mesh filename="package://moobot_description/mesh/avare_teker_coarse.stl" scale="0.001 0.001 0.001"/>
      </geometry>     
    </visual>

    <collision>
      <origin xyz="0 0 0" rpy="0 1.570796 0"/>
      <geometry>
        <cylinder length="0.022" radius="0.0375"/>
      </geometry>
    </collision>
    
    <inertial>
      <origin xyz="0 0 0" rpy="0 0 0"/>
      <mass value="0.1"/>
      <inertia ixx="0.0002" ixy="0" ixz="0"
               iyy="0.0002" iyz="0"
               izz="0.0002" />
    </inertial>
  </link> 

  <joint name="RLC_joint" type="continuous">
    <parent link="RLCC_link"/>
    <child link="RLC_link"/>
    <origin xyz="-0.0265 0.08205 0" rpy="1.570796 -1.570796 0"/>
    <axis xyz="1 0 0"/>
  </joint>

<link name="RLC_link">
    <visual>
      <origin xyz="0 0 0" rpy="0 0 0"/>
      <geometry>
        <mesh filename="package://moobot_description/mesh/avare_teker_coarse.stl" scale="0.001 0.001 0.001"/>
      </geometry>      
    </visual>

    <collision>
      <origin xyz="0 0 0" rpy="0 1.570796 0"/>
      <geometry>
        <cylinder length="0.022" radius="0.0375"/>
      </geometry>
    </collision>
    
    <inertial>
      <origin xyz="0 0 0" rpy="0 0 0"/>
      <mass value="0.1"/>
      <inertia ixx="0.0002" ixy="0" ixz="0"
               iyy="0.0002" iyz="0"
               izz="0.0002" />
    </inertial>
  </link> 

    <joint name="RRC_joint" type="continuous">
    <parent link="RRCC_link"/>
    <child link="RRC_link"/>
    <origin xyz="-0.0265 0.08205 0" rpy="1.570796 -1.570796 0"/>
    <axis xyz="1 0 0"/>
  </joint>

<link name="RRC_link">
    <visual>
      <origin xyz="0 0 0" rpy="0 0 0"/>
      <geometry>
        <mesh filename="package://moobot_description/mesh/avare_teker_coarse.stl" scale="0.001 0.001 0.001"/>
      </geometry>      
    </visual>

    <collision>
      <origin xyz="0 0 0" rpy="0 1.570796 0"/>
      <geometry>
        <cylinder length="0.022" radius="0.0375"/>
      </geometry>
    </collision>
    
    <inertial>
      <origin xyz="0 0 0" rpy="0 0 0"/>
      <mass value="0.1"/>
      <inertia ixx="0.0002" ixy="0" ixz="0"
               iyy="0.0002" iyz="0"
               izz="0.0002" />
    </inertial>
  </link> 

<!-- Scanner -->
<!-- Front Scanner -->
<joint name="front_scan_joint" type="fixed">
    <parent link="base_link"/>
    <child link="front_scan_link"/>
    <origin xyz="0.35 0 0.2232185" rpy="0 0 0"/>
  </joint>

  <link name="front_scan_link">
    <visual>
      <origin xyz="0 0 -0.067" rpy="0 0 0"/>
      <geometry>
        <mesh filename="package://moobot_description/mesh/hokuyo_coarse.stl" scale="0.001 0.001 0.001"/>
      </geometry>
    </visual>

    <collision>
      <origin xyz="0 0 -0.01675" rpy="0 0 0"/>
      <!-- <origin xyz="0.015 0 -0.0065" rpy="0 0 0"/> -->
      <geometry>
        <box size="0.080 0.080 0.080"/>
      </geometry>
    </collision>

    <inertial>
      <mass value="0.114" />
      <origin xyz="0 0 0" />
      <inertia ixx="0.001" ixy="0.0" ixz="0.0"
               iyy="0.001" iyz="0.0"
               izz="0.001" />
    </inertial>
  </link>

<joint name="rear_scan_joint" type="fixed">
    <parent link="base_link"/>
    <child link="rear_scan_link"/>
    <origin xyz="-0.35 -0.015 0.2232185" rpy="0 0 3.1415"/>
  </joint>

  <link name="rear_scan_link">
    <visual>
      <origin xyz="0 0 -0.067" rpy="0 0 0"/>
      <geometry>
        <mesh filename="package://moobot_description/mesh/hokuyo_coarse.stl" scale="0.001 0.001 0.001"/>
      </geometry>
    </visual>

    <collision>
      <origin xyz="0 0 -0.01675" rpy="0 0 0"/>
      <!-- <origin xyz="0.015 0 -0.0065" rpy="0 0 0"/> -->
      <geometry>
        <box size="0.080 0.080 0.080"/>
      </geometry>
    </collision>

    <inertial>
      <mass value="0.114" />
      <origin xyz="0 0 0" />
      <inertia ixx="0.001" ixy="0.0" ixz="0.0"
               iyy="0.001" iyz="0.0"
               izz="0.001" />
    </inertial>
  </link>

</robot>
