<?xml version="1.0"?>
<robot name="moobot" xmlns:xacro="http://ros.org/wiki/xacro">
  <xacro:include filename="$(find moobot_description)/urdf/common_properties.xacro" />
  <xacro:include filename="$(find moobot_description)/urdf/moobot.gazebo.xacro" />

  <!-- AGV Base -->

  <link name="base_link">
    <visual>
      <origin xyz="0 0 0" rpy="0 0 0" />
      <geometry>
        <mesh filename="package://moobot_description/mesh/logos_maxi_base.stl" scale="0.001 0.001 0.001" />
      </geometry>
    </visual>
    <!-- -->
    <collision>
      <origin xyz="0 0 0" rpy="0 0 0" />
      <geometry>
        <mesh filename="package://moobot_description/mesh/logos_maxi_base.stl" scale="0.001 0.001 0.001" />
        <!-- <box size="1.655 0.784 0.23" /> -->
      </geometry>
    </collision>
    <inertial>
      <origin xyz="0 0 0" rpy="0 0 0" />
      <mass value="289" />
      <inertia ixx="28.034" ixy="0.669" ixz="-2.355"
        iyy="96.827" iyz="0.232"
        izz="108.149" />
    </inertial>
  </link>

  <link name="base_footprint" />

  <joint name="base_joint" type="fixed">
    <parent link="base_footprint" />
    <child link="base_link" />
    <origin xyz="0 0 0" rpy="0 0 0" />
  </joint>

  <!-- Rear Right Mid Wheel Joint  -->
  <joint name="RRM_wheel_joint" type="continuous">
    <parent link="base_link" />
    <child link="RRM_wheel_link" />
    <origin xyz="0.0 -0.2235 0.105" rpy="0 0 0" />
    <axis xyz="0 1 0" />
    <dynamics damping="1" friction="0" />
    <limit effort="2" velocity="1.0" />
  </joint>

  <!-- Rear Right Mid Wheel Link  -->
  <link name="RRM_wheel_link">
    <visual>
      <origin xyz="0 0 0" rpy="0 0 0" />
      <geometry>
        <mesh filename="package://moobot_description/mesh/mid_wheel.stl" scale="0.001 0.001 0.001" />
      </geometry>
    </visual>

    <collision>
      <origin xyz="0 0 0" rpy="0 0 0" />
      <geometry>
        <cylinder length="0.0835" radius="0.105" />
      </geometry>
    </collision>

    <inertial>
      <mass value="1.5" />
      <origin xyz="0 0 0" />
      <inertia ixx="0.006751005" ixy="0.0" ixz="0.000001355"
        iyy="0.011935781" iyz="0.0"
        izz="0.006746312" />
    </inertial>
  </link>


  <!-- Rear Left Mid Wheel Joint  -->
  <joint name="RLM_wheel_joint" type="continuous">
    <parent link="base_link" />
    <child link="RLM_wheel_link" />
    <origin xyz="0.0 0.2235 0.105" rpy="0 0 0" />
    <axis xyz="0 1 0" />
    <dynamics damping="1" friction="0" />
    <limit effort="2" velocity="1.0" />
  </joint>

  <!-- Rear Left Mid Wheel Link  -->
  <link name="RLM_wheel_link">
    <visual>
      <origin xyz="0 0 0" rpy="0 0 3.141592654" />
      <geometry>
        <mesh filename="package://moobot_description/mesh/mid_wheel.stl" scale="0.001 0.001 0.001" />
      </geometry>
    </visual>

    <collision>
      <origin xyz="0 0 0" rpy="0 0 0" />
      <geometry>
        <cylinder length="0.0835" radius="0.105" />
      </geometry>
    </collision>

    <inertial>
      <mass value="1.5" />
      <origin xyz="0 0 0" />
      <inertia ixx="0.006751005" ixy="0.0" ixz="0.000001355"
        iyy="0.011935781" iyz="0.0"
        izz="0.006746312" />
    </inertial>
  </link>

  <!-- Scanner -->
  <!-- Front Scanner -->
  <joint name="front_scan_joint" type="fixed">
    <parent link="base_link" />
    <child link="front_scan_link" />
    <origin xyz="0.80612 0.3712 0.185" rpy="3.141592 0 0.7853981634" />
  </joint>

  <link name="front_scan_link">
    <visual>
      <origin xyz="0 0 0" rpy="0 0 0" />
      <geometry>
        <mesh filename="package://moobot_description/mesh/nanoscan.stl" scale="0.001 0.001 0.001" />
      </geometry>
    </visual>
    
    <inertial>
      <mass value="0.114" />
      <origin xyz="0 0 0" />
      <inertia ixx="0.001" ixy="0.0" ixz="0.0"
        iyy="0.001" iyz="0.0"
        izz="0.001" />
    </inertial>
  </link>

  <joint name="rear_scan_joint" type="fixed">
    <parent link="base_link" />
    <child link="rear_scan_link" />
    <origin xyz="-0.80612 -0.3712 0.185" rpy="3.141592 0  3.926990817 " />
  </joint>

  <link name="rear_scan_link">
    <visual>
      <origin xyz="0 0 0" rpy="0 0 0" />
      <geometry>
        <mesh filename="package://moobot_description/mesh/nanoscan.stl" scale="0.001 0.001 0.001" />
      </geometry>
    </visual>

    <inertial>
      <mass value="0.114" />
      <origin xyz="0 0 0" />
      <inertia ixx="0.001" ixy="0.0" ixz="0.0"
        iyy="0.001" iyz="0.0"
        izz="0.001" />
    </inertial>
  </link>

</robot>
